import { generateSummary } from '@/lib/ai/passive/generateSummary';
import logger from '@/lib/utils/logger';

// Mock the logger
jest.mock('@/lib/utils/logger', () => ({
  log: jest.fn(),
  error: jest.fn(),
}));

// Mock setTimeout used in the placeholder AI call
// jest.useFakeTimers(); // Use fake timers if testing actual delays is needed

describe('generateSummary', () => {
  beforeEach(() => {
    // Reset mocks before each test
    jest.clearAllMocks();
  });

  it('should generate a summary successfully for valid content', async () => {
    const content = 'This is the report content.';
    const expectedSummary = `This is a generated summary for the content starting with: "${content.substring(0, 30)}..."`;
    const expectedMeta = expect.objectContaining({ // Use objectContaining for flexibility
      modelUsed: 'mock-model-v1',
      cost: 0.0001,
    });

    const result = await generateSummary(content);

    expect(result.summary).toBe(expectedSummary);
    expect(result.meta).toEqual(expectedMeta);
    expect(logger.log).toHaveBeenCalledWith('[generateSummary] Starting execution.');
    expect(logger.log).toHaveBeenCalledWith('[generateSummary] Attempting AI call (mock)...');
    expect(logger.log).toHaveBeenCalledWith(
        expect.stringContaining('[generateSummary] AI call successful.'),
        expect.objectContaining({ summaryLength: expectedSummary.length })
    );
    expect(logger.log).toHaveBeenCalledWith('[generateSummary] Finished execution successfully.');
    expect(logger.error).not.toHaveBeenCalled();
  });

  it('should return empty summary and log error for null content', async () => {
    const content = null;
    const result = await generateSummary(content);

    expect(result.summary).toBe('');
    expect(result.meta).toEqual({ modelUsed: 'N/A', error: 'Invalid input content' });
    expect(logger.log).toHaveBeenCalledWith('[generateSummary] Starting execution.');
    expect(logger.error).toHaveBeenCalledWith('[generateSummary] Invalid input content provided.');
    expect(logger.log).not.toHaveBeenCalledWith(expect.stringContaining('Attempting AI call'));
  });

  it('should return empty summary and log error for empty string content', async () => {
    const content = '   '; // Whitespace only
    const result = await generateSummary(content);

    expect(result.summary).toBe('');
    expect(result.meta).toEqual({ modelUsed: 'N/A', error: 'Invalid input content' });
    expect(logger.log).toHaveBeenCalledWith('[generateSummary] Starting execution.');
    expect(logger.error).toHaveBeenCalledWith('[generateSummary] Invalid input content provided.');
  });

  // Note: Testing the actual error thrown by the mock requires modifying the mock itself.
  // This test assumes the current mock structure which doesn't easily simulate internal errors.
  // If the placeholder involved a real (mocked) API client, we could make that client throw.
  // For now, we test that if an error *were* thrown, it would be logged and re-thrown.

  // Example of how you might test error handling if the mock could throw:
  // it('should log error and re-throw if the AI call fails', async () => {
  //   const content = 'Valid content.';
  //   const mockError = new Error('AI API Error');
  //
  //   // Modify the mock setup or use jest.spyOn if the mock logic was more complex
  //   // For the current simple mock, this is harder. Let's assume we could force the try block's catch:
  //   const originalTimeout = global.setTimeout;
  //   global.setTimeout = jest.fn(() => { throw mockError; }); // Crude way to force catch
  //
  //   await expect(generateSummary(content)).rejects.toThrow('[generateSummary] AI call failed: AI API Error');
  //
  //   expect(logger.error).toHaveBeenCalledWith('[generateSummary] AI call failed.', mockError);
  //   expect(logger.log).toHaveBeenCalledWith('[generateSummary] Finished execution with error.');
  //
  //   global.setTimeout = originalTimeout; // Restore original setTimeout
  // });
});